Исключения - механизм, позволяющий отслеживать и реагировать на нештатные ситуации в момент выполнения программы.
Исключение это объект [[Классы|класса]] Exception двигающийся вверх по стеку функций, если происходит выбрасывание исключения.
#### **Блок try-except**
Блок имеет следующий синтаксис:
```Python
try:
	<код потеницально способный привести к критической ошибке>
except:
	<действия в случае ее возникновения>
```
Пример:
```Python
try:
  fruits = ["apple", "orange", 82, "pomelo"]
  longest_fruit = max(fruits, key=lambda element: len(element))
  print(longest_fruit)
except Exception as error:
  print(f"Exeption occured - {type(error).__name__}: {error}")
```
Вывод в консоль: ```Exeption occured - TypeError: object of type 'int' has no len()```

Данный код специально написан таким образом, чтобы привести к возникновению критической ошибки - исключения, сигнализирующего о том, что для типа int не [[Dunder-методы|переопределена функция]] len(). Используя атрибут __name__, мы можем узнать конкретный тип возникшего исключения. В данном коде, мы ловим исключение Exception, а это базовый класс для всех исключений, которые существуют, то есть, если бы в этом коде происходило деление на ноль, данный блок except отработал бы также, и далее передаем это исключение как "error". Если бы в блок except мы поместили исключение TypeError, то оно бы отработало только в случае возникновения конкретно этой ошибки. Помимо имеющихся типов исключений в языке Python можно добавлять [[Механизм исключений|свои типы исключений]].

"Выбрасывать" исключения самостоятельно можно с помощью ключевого слова ```raise```:
```Python
try:
  raise Exception("Some Error")
except Exception as error:
  print(f"Exeption occured - {type(error).__name__}: {error}")
```
Вывод в консоль: ```Exeption occured - Exception: Some Error```.
В данном случае мы сгенерировали исключение базового типа ```Exception```и поймали его в блоке except.
Если обработка исключения не предполагается конкретно в данном блоке except, то его можно передать следующему обработчику исключений с помощью еще одного ключевого слова raise в блоке except, если после перевыбрасывания исключения оно не будет поймано, исключение приведет к аварийному завершению программы:
```Python
try:
  raise Exception("Some Error")
except Exception as error:
  raise
```
Вывод в консоль:
```
Traceback (most recent call last):
  File "d:\Dev\pip\tests\strings.py", line 2, in <module>
    raise Exception("Some Error")
Exception: Some Error
```
Как видно из вывода, данное исключение привело к аварийному завершению программы.